Workbook
Name DBR: Calculator!$F$2
Name HPE: Calculator!$I$2
Name MBR: Calculator!$C$2
Name ND: Calculator!$L$2
Name NDP: Calculator!#REF!
Name Salary: Calculator!$C$2

Sheet Daily Time Record
B1: Date | C1: Month | D1: Day Status | E1: Attendance Status | F1: Rest Day? | G1: Work Hours | H1: Late | I1: Undertime | J1: Overtime | K1: Night Differential | L1: Night Differential OT | M1: Multiplier | N1: Multiplier OT | O1: Daily Salary | Q1: Cutoff Salary
A2: FEBRUARY | B2: 46070 | C2: February | D2: =_xlfn.XLOOKUP(B2,'Holidays 2026'!$A$2:$A$27,'Holidays 2026'!$G$2:$G$27,"Regular",0,1) -> Special Working Holiday | E2: Worked | F2: =IF(OR(TEXT(B2,"dddd")="Saturday",TEXT(B2,"dddd")="Sunday"),"Yes","No") -> No | G2: {=_xlfn.IFS(OR(E2="Worked",E2="Approved Sick Leave",E2="Approved Vacation Leave",E2="Holiday"),8,E2="","",OR(E2="Absent",E2="Rest Day",E2="Sick Leave Without Pay",E2="Vacation Leave Without Pay"),0)} -> 8 | H2: 0 | I2: 0 | J2: 2 | K2: =IF(E2="Rest Day",0,"7") -> 7 | M2: {=_xlfn.IFS( OR(E2="Absent", E2="Sick Leave Without Pay", E2="Vacation Leave Without Pay", E2="Rest Day"), 0, OR(E2="Approved Sick Leave", E2="Approved Vacation Leave"), 1, D2="Regular Non-Working Holiday", IF(E2="Worked", IF(F2="Yes",2.6,2), 1), D2="Regular Working Holiday", IF(E2="Worked", IF(F2="Yes",2.6,2), 1), D2="Special Non-Working Holiday", IF(E2="Worked", IF(F2="Yes",1.5,1.3), 0), D2="Special Working Holiday", 1, D2="Regular", IF(F2="Yes", IF(E2="Worked",1.3,0), IF(E2="Worked",1,0) ) )} -> 1 | N2: {=_xlfn.IFS( F2="No", _xlfn.IFS( D2="Regular", 1.25, OR(D2="Special Working Holiday", D2="Special Non-Working Holiday"), 1.3*1.3, OR(D2="Regular Working Holiday", D2="Regular Non-Working Holiday"), 2*1.3 ), F2="Yes", _xlfn.IFS( D2="Regular", 1.3*1.3, OR(D2="Special Working Holiday", D2="Special Non-Working Holiday"), 1.5*1.3, OR(D2="Regular Working Holiday", D2="Regular Non-Working Holiday"), 2.6*1.3 ) )} -> 1.69 | O2: =IF(E2<>"",(G2*HPE*M2)+(N2*HPE*J2)+(K2*ND),"") -> 1110.8046 | P2: Start | Q2: {=IF(P2="Payday",LOOKUP(2,1/((#REF!=#REF!)*(P$2:P2="Cut-off")),#REF!),"")}
B3: 46071 | C3: February | D3: =_xlfn.XLOOKUP(B3,'Holidays 2026'!$A$2:$A$27,'Holidays 2026'!$G$2:$G$27,"Regular",0,1) -> Regular | E3: Worked | F3: =IF(OR(TEXT(B3,"dddd")="Saturday",TEXT(B3,"dddd")="Sunday"),"Yes","No") -> No | G3: {=_xlfn.IFS(OR(E3="Worked",E3="Approved Sick Leave",E3="Approved Vacation Leave",E3="Holiday"),8,E3="","",OR(E3="Absent",E3="Rest Day",E3="Sick Leave Without Pay",E3="Vacation Leave Without Pay"),0)} -> 8 | H3: 0 | I3: 0 | J3: 0 | K3: =IF(E3="Rest Day",0,"7") -> 7 | M3: {=_xlfn.IFS( OR(E3="Absent", E3="Sick Leave Without Pay", E3="Vacation Leave Without Pay", E3="Rest Day"), 0, OR(E3="Approved Sick Leave", E3="Approved Vacation Leave"), 1, D3="Regular Non-Working Holiday", IF(E3="Worked", IF(F3="Yes",2.6,2), 1), D3="Regular Working Holiday", IF(E3="Worked", IF(F3="Yes",2.6,2), 1), D3="Special Non-Working Holiday", IF(E3="Worked", IF(F3="Yes",1.5,1.3), 0), D3="Special Working Holiday", 1, D3="Regular", IF(F3="Yes", IF(E3="Worked",1.3,0), IF(E3="Worked",1,0) ) )} -> 1 | N3: {=_xlfn.IFS( F3="No", _xlfn.IFS( D3="Regular", 1.25, OR(D3="Special Working Holiday", D3="Special Non-Working Holiday"), 1.3*1.3, OR(D3="Regular Working Holiday", D3="Regular Non-Working Holiday"), 2*1.3 ), F3="Yes", _xlfn.IFS( D3="Regular", 1.3*1.3, OR(D3="Special Working Holiday", D3="Special Non-Working Holiday"), 1.5*1.3, OR(D3="Regular Working Holiday", D3="Regular Non-Working Holiday"), 2.6*1.3 ) )} -> 1.25 | O3: =IF(E3<>"",(G3*HPE*M3)+(N3*HPE*J3)+(K3*ND),"") -> 800 | P3: {=_xlfn.IFS( OR(DAY(B3)=5, DAY(B3)=20), "Cut-off", OR( DAY(B3)=15, DAY(B3)=DAY(EOMONTH(B3,0)) ), "Payday", TRUE, "" )}
B4: 46072 | C4: February | D4: =_xlfn.XLOOKUP(B4,'Holidays 2026'!$A$2:$A$27,'Holidays 2026'!$G$2:$G$27,"Regular",0,1) -> Regular | E4: Worked | F4: =IF(OR(TEXT(B4,"dddd")="Saturday",TEXT(B4,"dddd")="Sunday"),"Yes","No") -> No | G4: {=_xlfn.IFS(OR(E4="Worked",E4="Approved Sick Leave",E4="Approved Vacation Leave",E4="Holiday"),8,E4="","",OR(E4="Absent",E4="Rest Day",E4="Sick Leave Without Pay",E4="Vacation Leave Without Pay"),0)} -> 8 | H4: 0 | I4: 0 | J4: 0 | K4: =IF(E4="Rest Day",0,"7") -> 7 | M4: {=_xlfn.IFS( OR(E4="Absent", E4="Sick Leave Without Pay", E4="Vacation Leave Without Pay", E4="Rest Day"), 0, OR(E4="Approved Sick Leave", E4="Approved Vacation Leave"), 1, D4="Regular Non-Working Holiday", IF(E4="Worked", IF(F4="Yes",2.6,2), 1), D4="Regular Working Holiday", IF(E4="Worked", IF(F4="Yes",2.6,2), 1), D4="Special Non-Working Holiday", IF(E4="Worked", IF(F4="Yes",1.5,1.3), 0), D4="Special Working Holiday", 1, D4="Regular", IF(F4="Yes", IF(E4="Worked",1.3,0), IF(E4="Worked",1,0) ) )} -> 1 | N4: {=_xlfn.IFS( F4="No", _xlfn.IFS( D4="Regular", 1.25, OR(D4="Special Working Holiday", D4="Special Non-Working Holiday"), 1.3*1.3, OR(D4="Regular Working Holiday", D4="Regular Non-Working Holiday"), 2*1.3 ), F4="Yes", _xlfn.IFS( D4="Regular", 1.3*1.3, OR(D4="Special Working Holiday", D4="Special Non-Working Holiday"), 1.5*1.3, OR(D4="Regular Working Holiday", D4="Regular Non-Working Holiday"), 2.6*1.3 ) )} -> 1.25 | O4: =IF(E4<>"",(G4*HPE*M4)+(N4*HPE*J4)+(K4*ND),"") -> 800 | P4: {=_xlfn.IFS( OR(DAY(B4)=5, DAY(B4)=20), "Cut-off", OR( DAY(B4)=15, DAY(B4)=DAY(EOMONTH(B4,0)) ), "Payday", TRUE, "" )}
B5: 46073 | C5: February | D5: =_xlfn.XLOOKUP(B5,'Holidays 2026'!$A$2:$A$27,'Holidays 2026'!$G$2:$G$27,"Regular",0,1) -> Regular | E5: Worked | F5: =IF(OR(TEXT(B5,"dddd")="Saturday",TEXT(B5,"dddd")="Sunday"),"Yes","No") -> No | G5: {=_xlfn.IFS(OR(E5="Worked",E5="Approved Sick Leave",E5="Approved Vacation Leave",E5="Holiday"),8,E5="","",OR(E5="Absent",E5="Rest Day",E5="Sick Leave Without Pay",E5="Vacation Leave Without Pay"),0)} -> 8 | H5: 0 | I5: 0 | J5: 0 | K5: =IF(E5="Rest Day",0,"7") -> 7 | M5: {=_xlfn.IFS( OR(E5="Absent", E5="Sick Leave Without Pay", E5="Vacation Leave Without Pay", E5="Rest Day"), 0, OR(E5="Approved Sick Leave", E5="Approved Vacation Leave"), 1, D5="Regular Non-Working Holiday", IF(E5="Worked", IF(F5="Yes",2.6,2), 1), D5="Regular Working Holiday", IF(E5="Worked", IF(F5="Yes",2.6,2), 1), D5="Special Non-Working Holiday", IF(E5="Worked", IF(F5="Yes",1.5,1.3), 0), D5="Special Working Holiday", 1, D5="Regular", IF(F5="Yes", IF(E5="Worked",1.3,0), IF(E5="Worked",1,0) ) )} -> 1 | N5: {=_xlfn.IFS( F5="No", _xlfn.IFS( D5="Regular", 1.25, OR(D5="Special Working Holiday", D5="Special Non-Working Holiday"), 1.3*1.3, OR(D5="Regular Working Holiday", D5="Regular Non-Working Holiday"), 2*1.3 ), F5="Yes", _xlfn.IFS( D5="Regular", 1.3*1.3, OR(D5="Special Working Holiday", D5="Special Non-Working Holiday"), 1.5*1.3, OR(D5="Regular Working Holiday", D5="Regular Non-Working Holiday"), 2.6*1.3 ) )} -> 1.25 | O5: =IF(E5<>"",(G5*HPE*M5)+(N5*HPE*J5)+(K5*ND),"") -> 800 | P5: {=_xlfn.IFS( OR(DAY(B5)=5, DAY(B5)=20), "Cut-off", OR(DAY(B5)=6, DAY(B5)=21), "Start", OR( DAY(B5)=15, DAY(B5)=30, AND(MONTH(B5)=2,DAY(B5)=DAY(EOMONTH(B5,0))) ), "Payday", TRUE, "" )} -> Cut-off
B6: 46074 | C6: February | D6: =_xlfn.XLOOKUP(B6,'Holidays 2026'!$A$2:$A$27,'Holidays 2026'!$G$2:$G$27,"Regular",0,1) -> Regular | E6: Rest Day | F6: =IF(OR(TEXT(B6,"dddd")="Saturday",TEXT(B6,"dddd")="Sunday"),"Yes","No") -> Yes | G6: {=_xlfn.IFS(OR(E6="Worked",E6="Approved Sick Leave",E6="Approved Vacation Leave",E6="Holiday"),8,E6="","",OR(E6="Absent",E6="Rest Day",E6="Sick Leave Without Pay",E6="Vacation Leave Without Pay"),0)} -> 0 | H6: 0 | I6: 0 | J6: 0 | K6: =IF(E6="Rest Day",0,"7") -> 0 | M6: {=_xlfn.IFS( OR(E6="Absent", E6="Sick Leave Without Pay", E6="Vacation Leave Without Pay", E6="Rest Day"), 0, OR(E6="Approved Sick Leave", E6="Approved Vacation Leave"), 1, D6="Regular Non-Working Holiday", IF(E6="Worked", IF(F6="Yes",2.6,2), 1), D6="Regular Working Holiday", IF(E6="Worked", IF(F6="Yes",2.6,2), 1), D6="Special Non-Working Holiday", IF(E6="Worked", IF(F6="Yes",1.5,1.3), 0), D6="Special Working Holiday", 1, D6="Regular", IF(F6="Yes", IF(E6="Worked",1.3,0), IF(E6="Worked",1,0) ) )} -> 0 | N6: {=_xlfn.IFS( F6="No", _xlfn.IFS( D6="Regular", 1.25, OR(D6="Special Working Holiday", D6="Special Non-Working Holiday"), 1.3*1.3, OR(D6="Regular Working Holiday", D6="Regular Non-Working Holiday"), 2*1.3 ), F6="Yes", _xlfn.IFS( D6="Regular", 1.3*1.3, OR(D6="Special Working Holiday", D6="Special Non-Working Holiday"), 1.5*1.3, OR(D6="Regular Working Holiday", D6="Regular Non-Working Holiday"), 2.6*1.3 ) )} -> 1.69 | O6: =IF(E6<>"",(G6*HPE*M6)+(N6*HPE*J6)+(K6*ND),"") -> 0 | P6: {=_xlfn.IFS( OR(DAY(B6)=5, DAY(B6)=20), "Cut-off", OR(DAY(B6)=6, DAY(B6)=21), "Start", OR( DAY(B6)=15, DAY(B6)=30, AND(MONTH(B6)=2,DAY(B6)=DAY(EOMONTH(B6,0))) ), "Payday", TRUE, "" )} -> Start
B7: 46075 | C7: February | D7: =_xlfn.XLOOKUP(B7,'Holidays 2026'!$A$2:$A$27,'Holidays 2026'!$G$2:$G$27,"Regular",0,1) -> Regular | E7: Rest Day | F7: =IF(OR(TEXT(B7,"dddd")="Saturday",TEXT(B7,"dddd")="Sunday"),"Yes","No") -> Yes | G7: {=_xlfn.IFS(OR(E7="Worked",E7="Approved Sick Leave",E7="Approved Vacation Leave",E7="Holiday"),8,E7="","",OR(E7="Absent",E7="Rest Day",E7="Sick Leave Without Pay",E7="Vacation Leave Without Pay"),0)} -> 0 | H7: 0 | I7: 0 | J7: 0 | K7: =IF(E7="Rest Day",0,"7") -> 0 | M7: {=_xlfn.IFS( OR(E7="Absent", E7="Sick Leave Without Pay", E7="Vacation Leave Without Pay", E7="Rest Day"), 0, OR(E7="Approved Sick Leave", E7="Approved Vacation Leave"), 1, D7="Regular Non-Working Holiday", IF(E7="Worked", IF(F7="Yes",2.6,2), 1), D7="Regular Working Holiday", IF(E7="Worked", IF(F7="Yes",2.6,2), 1), D7="Special Non-Working Holiday", IF(E7="Worked", IF(F7="Yes",1.5,1.3), 0), D7="Special Working Holiday", 1, D7="Regular", IF(F7="Yes", IF(E7="Worked",1.3,0), IF(E7="Worked",1,0) ) )} -> 0 | N7: {=_xlfn.IFS( F7="No", _xlfn.IFS( D7="Regular", 1.25, OR(D7="Special Working Holiday", D7="Special Non-Working Holiday"), 1.3*1.3, OR(D7="Regular Working Holiday", D7="Regular Non-Working Holiday"), 2*1.3 ), F7="Yes", _xlfn.IFS( D7="Regular", 1.3*1.3, OR(D7="Special Working Holiday", D7="Special Non-Working Holiday"), 1.5*1.3, OR(D7="Regular Working Holiday", D7="Regular Non-Working Holiday"), 2.6*1.3 ) )} -> 1.69 | O7: =IF(E7<>"",(G7*HPE*M7)+(N7*HPE*J7)+(K7*ND),"") -> 0 | P7: {=_xlfn.IFS( OR(DAY(B7)=5, DAY(B7)=20), "Cut-off", OR(DAY(B7)=6, DAY(B7)=21), "Start", OR( DAY(B7)=15, DAY(B7)=30, AND(MONTH(B7)=2,DAY(B7)=DAY(EOMONTH(B7,0))) ), "Payday", TRUE, "" )}
B8: 46076 | C8: February | D8: =_xlfn.XLOOKUP(B8,'Holidays 2026'!$A$2:$A$27,'Holidays 2026'!$G$2:$G$27,"Regular",0,1) -> Regular | E8: Worked | F8: =IF(OR(TEXT(B8,"dddd")="Saturday",TEXT(B8,"dddd")="Sunday"),"Yes","No") -> No | G8: {=_xlfn.IFS(OR(E8="Worked",E8="Approved Sick Leave",E8="Approved Vacation Leave",E8="Holiday"),8,E8="","",OR(E8="Absent",E8="Rest Day",E8="Sick Leave Without Pay",E8="Vacation Leave Without Pay"),0)} -> 8 | H8: 0 | I8: 0 | J8: 0 | K8: =IF(E8="Rest Day",0,"7") -> 7 | M8: {=_xlfn.IFS( OR(E8="Absent", E8="Sick Leave Without Pay", E8="Vacation Leave Without Pay", E8="Rest Day"), 0, OR(E8="Approved Sick Leave", E8="Approved Vacation Leave"), 1, D8="Regular Non-Working Holiday", IF(E8="Worked", IF(F8="Yes",2.6,2), 1), D8="Regular Working Holiday", IF(E8="Worked", IF(F8="Yes",2.6,2), 1), D8="Special Non-Working Holiday", IF(E8="Worked", IF(F8="Yes",1.5,1.3), 0), D8="Special Working Holiday", 1, D8="Regular", IF(F8="Yes", IF(E8="Worked",1.3,0), IF(E8="Worked",1,0) ) )} -> 1 | N8: {=_xlfn.IFS( F8="No", _xlfn.IFS( D8="Regular", 1.25, OR(D8="Special Working Holiday", D8="Special Non-Working Holiday"), 1.3*1.3, OR(D8="Regular Working Holiday", D8="Regular Non-Working Holiday"), 2*1.3 ), F8="Yes", _xlfn.IFS( D8="Regular", 1.3*1.3, OR(D8="Special Working Holiday", D8="Special Non-Working Holiday"), 1.5*1.3, OR(D8="Regular Working Holiday", D8="Regular Non-Working Holiday"), 2.6*1.3 ) )} -> 1.25 | O8: =IF(E8<>"",(G8*HPE*M8)+(N8*HPE*J8)+(K8*ND),"") -> 800 | P8: {=_xlfn.IFS( OR(DAY(B8)=5, DAY(B8)=20), "Cut-off", OR(DAY(B8)=6, DAY(B8)=21), "Start", OR( DAY(B8)=15, DAY(B8)=30, AND(MONTH(B8)=2,DAY(B8)=DAY(EOMONTH(B8,0))) ), "Payday", TRUE, "" )}
B9: 46077 | C9: February | D9: =_xlfn.XLOOKUP(B9,'Holidays 2026'!$A$2:$A$27,'Holidays 2026'!$G$2:$G$27,"Regular",0,1) -> Regular | E9: Worked | F9: =IF(OR(TEXT(B9,"dddd")="Saturday",TEXT(B9,"dddd")="Sunday"),"Yes","No") -> No | G9: {=_xlfn.IFS(OR(E9="Worked",E9="Approved Sick Leave",E9="Approved Vacation Leave",E9="Holiday"),8,E9="","",OR(E9="Absent",E9="Rest Day",E9="Sick Leave Without Pay",E9="Vacation Leave Without Pay"),0)} -> 8 | H9: 0 | I9: 0 | J9: 0 | K9: =IF(E9="Rest Day",0,"7") -> 7 | M9: {=_xlfn.IFS( OR(E9="Absent", E9="Sick Leave Without Pay", E9="Vacation Leave Without Pay", E9="Rest Day"), 0, OR(E9="Approved Sick Leave", E9="Approved Vacation Leave"), 1, D9="Regular Non-Working Holiday", IF(E9="Worked", IF(F9="Yes",2.6,2), 1), D9="Regular Working Holiday", IF(E9="Worked", IF(F9="Yes",2.6,2), 1), D9="Special Non-Working Holiday", IF(E9="Worked", IF(F9="Yes",1.5,1.3), 0), D9="Special Working Holiday", 1, D9="Regular", IF(F9="Yes", IF(E9="Worked",1.3,0), IF(E9="Worked",1,0) ) )} -> 1 | N9: {=_xlfn.IFS( F9="No", _xlfn.IFS( D9="Regular", 1.25, OR(D9="Special Working Holiday", D9="Special Non-Working Holiday"), 1.3*1.3, OR(D9="Regular Working Holiday", D9="Regular Non-Working Holiday"), 2*1.3 ), F9="Yes", _xlfn.IFS( D9="Regular", 1.3*1.3, OR(D9="Special Working Holiday", D9="Special Non-Working Holiday"), 1.5*1.3, OR(D9="Regular Working Holiday", D9="Regular Non-Working Holiday"), 2.6*1.3 ) )} -> 1.25 | O9: =IF(E9<>"",(G9*HPE*M9)+(N9*HPE*J9)+(K9*ND),"") -> 800 | P9: {=_xlfn.IFS( OR(DAY(B9)=5, DAY(B9)=20), "Cut-off", OR(DAY(B9)=6, DAY(B9)=21), "Start", OR( DAY(B9)=15, DAY(B9)=30, AND(MONTH(B9)=2,DAY(B9)=DAY(EOMONTH(B9,0))) ), "Payday", TRUE, "" )}
B10: 46078 | C10: February | D10: =_xlfn.XLOOKUP(B10,'Holidays 2026'!$A$2:$A$27,'Holidays 2026'!$G$2:$G$27,"Regular",0,1) -> Regular | E10: Worked | F10: =IF(OR(TEXT(B10,"dddd")="Saturday",TEXT(B10,"dddd")="Sunday"),"Yes","No") -> No | G10: {=_xlfn.IFS(OR(E10="Worked",E10="Approved Sick Leave",E10="Approved Vacation Leave",E10="Holiday"),8,E10="","",OR(E10="Absent",E10="Rest Day",E10="Sick Leave Without Pay",E10="Vacation Leave Without Pay"),0)} -> 8 | H10: 0 | I10: 0 | J10: 0 | K10: =IF(E10="Rest Day",0,"7") -> 7 | M10: {=_xlfn.IFS( OR(E10="Absent", E10="Sick Leave Without Pay", E10="Vacation Leave Without Pay", E10="Rest Day"), 0, OR(E10="Approved Sick Leave", E10="Approved Vacation Leave"), 1, D10="Regular Non-Working Holiday", IF(E10="Worked", IF(F10="Yes",2.6,2), 1), D10="Regular Working Holiday", IF(E10="Worked", IF(F10="Yes",2.6,2), 1), D10="Special Non-Working Holiday", IF(E10="Worked", IF(F10="Yes",1.5,1.3), 0), D10="Special Working Holiday", 1, D10="Regular", IF(F10="Yes", IF(E10="Worked",1.3,0), IF(E10="Worked",1,0) ) )} -> 1 | N10: {=_xlfn.IFS( F10="No", _xlfn.IFS( D10="Regular", 1.25, OR(D10="Special Working Holiday", D10="Special Non-Working Holiday"), 1.3*1.3, OR(D10="Regular Working Holiday", D10="Regular Non-Working Holiday"), 2*1.3 ), F10="Yes", _xlfn.IFS( D10="Regular", 1.3*1.3, OR(D10="Special Working Holiday", D10="Special Non-Working Holiday"), 1.5*1.3, OR(D10="Regular Working Holiday", D10="Regular Non-Working Holiday"), 2.6*1.3 ) )} -> 1.25 | O10: =IF(E10<>"",(G10*HPE*M10)+(N10*HPE*J10)+(K10*ND),"") -> 800 | P10: {=_xlfn.IFS( OR(DAY(B10)=5, DAY(B10)=20), "Cut-off", OR(DAY(B10)=6, DAY(B10)=21), "Start", OR( DAY(B10)=15, DAY(B10)=30, AND(MONTH(B10)=2,DAY(B10)=DAY(EOMONTH(B10,0))) ), "Payday", TRUE, "" )}
B11: 46079 | C11: February | D11: =_xlfn.XLOOKUP(B11,'Holidays 2026'!$A$2:$A$27,'Holidays 2026'!$G$2:$G$27,"Regular",0,1) -> Regular | E11: Worked | F11: =IF(OR(TEXT(B11,"dddd")="Saturday",TEXT(B11,"dddd")="Sunday"),"Yes","No") -> No | G11: {=_xlfn.IFS(OR(E11="Worked",E11="Approved Sick Leave",E11="Approved Vacation Leave",E11="Holiday"),8,E11="","",OR(E11="Absent",E11="Rest Day",E11="Sick Leave Without Pay",E11="Vacation Leave Without Pay"),0)} -> 8 | H11: 0 | I11: 0 | J11: 0 | K11: =IF(E11="Rest Day",0,"7") -> 7 | M11: {=_xlfn.IFS( OR(E11="Absent", E11="Sick Leave Without Pay", E11="Vacation Leave Without Pay", E11="Rest Day"), 0, OR(E11="Approved Sick Leave", E11="Approved Vacation Leave"), 1, D11="Regular Non-Working Holiday", IF(E11="Worked", IF(F11="Yes",2.6,2), 1), D11="Regular Working Holiday", IF(E11="Worked", IF(F11="Yes",2.6,2), 1), D11="Special Non-Working Holiday", IF(E11="Worked", IF(F11="Yes",1.5,1.3), 0), D11="Special Working Holiday", 1, D11="Regular", IF(F11="Yes", IF(E11="Worked",1.3,0), IF(E11="Worked",1,0) ) )} -> 1 | N11: {=_xlfn.IFS( F11="No", _xlfn.IFS( D11="Regular", 1.25, OR(D11="Special Working Holiday", D11="Special Non-Working Holiday"), 1.3*1.3, OR(D11="Regular Working Holiday", D11="Regular Non-Working Holiday"), 2*1.3 ), F11="Yes", _xlfn.IFS( D11="Regular", 1.3*1.3, OR(D11="Special Working Holiday", D11="Special Non-Working Holiday"), 1.5*1.3, OR(D11="Regular Working Holiday", D11="Regular Non-Working Holiday"), 2.6*1.3 ) )} -> 1.25 | O11: =IF(E11<>"",(G11*HPE*M11)+(N11*HPE*J11)+(K11*ND),"") -> 800 | P11: {=_xlfn.IFS( OR(DAY(B11)=5, DAY(B11)=20), "Cut-off", OR(DAY(B11)=6, DAY(B11)=21), "Start", OR( DAY(B11)=15, DAY(B11)=30, AND(MONTH(B11)=2,DAY(B11)=DAY(EOMONTH(B11,0))) ), "Payday", TRUE, "" )}
B12: 46080 | C12: February | D12: =_xlfn.XLOOKUP(B12,'Holidays 2026'!$A$2:$A$27,'Holidays 2026'!$G$2:$G$27,"Regular",0,1) -> Regular | E12: Worked | F12: =IF(OR(TEXT(B12,"dddd")="Saturday",TEXT(B12,"dddd")="Sunday"),"Yes","No") -> No | G12: {=_xlfn.IFS(OR(E12="Worked",E12="Approved Sick Leave",E12="Approved Vacation Leave",E12="Holiday"),8,E12="","",OR(E12="Absent",E12="Rest Day",E12="Sick Leave Without Pay",E12="Vacation Leave Without Pay"),0)} -> 8 | H12: 0 | I12: 0 | J12: 0 | K12: =IF(E12="Rest Day",0,"7") -> 7 | M12: {=_xlfn.IFS( OR(E12="Absent", E12="Sick Leave Without Pay", E12="Vacation Leave Without Pay", E12="Rest Day"), 0, OR(E12="Approved Sick Leave", E12="Approved Vacation Leave"), 1, D12="Regular Non-Working Holiday", IF(E12="Worked", IF(F12="Yes",2.6,2), 1), D12="Regular Working Holiday", IF(E12="Worked", IF(F12="Yes",2.6,2), 1), D12="Special Non-Working Holiday", IF(E12="Worked", IF(F12="Yes",1.5,1.3), 0), D12="Special Working Holiday", 1, D12="Regular", IF(F12="Yes", IF(E12="Worked",1.3,0), IF(E12="Worked",1,0) ) )} -> 1 | N12: {=_xlfn.IFS( F12="No", _xlfn.IFS( D12="Regular", 1.25, OR(D12="Special Working Holiday", D12="Special Non-Working Holiday"), 1.3*1.3, OR(D12="Regular Working Holiday", D12="Regular Non-Working Holiday"), 2*1.3 ), F12="Yes", _xlfn.IFS( D12="Regular", 1.3*1.3, OR(D12="Special Working Holiday", D12="Special Non-Working Holiday"), 1.5*1.3, OR(D12="Regular Working Holiday", D12="Regular Non-Working Holiday"), 2.6*1.3 ) )} -> 1.25 | O12: =IF(E12<>"",(G12*HPE*M12)+(N12*HPE*J12)+(K12*ND),"") -> 800 | P12: {=_xlfn.IFS( OR(DAY(B12)=5, DAY(B12)=20), "Cut-off", OR(DAY(B12)=6, DAY(B12)=21), "Start", OR( DAY(B12)=15, DAY(B12)=30, AND(MONTH(B12)=2,DAY(B12)=DAY(EOMONTH(B12,0))) ), "Payday", TRUE, "" )}
B13: 46081 | C13: February | D13: =_xlfn.XLOOKUP(B13,'Holidays 2026'!$A$2:$A$27,'Holidays 2026'!$G$2:$G$27,"Regular",0,1) -> Regular | E13: Rest Day | F13: =IF(OR(TEXT(B13,"dddd")="Saturday",TEXT(B13,"dddd")="Sunday"),"Yes","No") -> Yes | G13: {=_xlfn.IFS(OR(E13="Worked",E13="Approved Sick Leave",E13="Approved Vacation Leave",E13="Holiday"),8,E13="","",OR(E13="Absent",E13="Rest Day",E13="Sick Leave Without Pay",E13="Vacation Leave Without Pay"),0)} -> 0 | H13: 0 | I13: 0 | J13: 0 | K13: =IF(E13="Rest Day",0,"7") -> 0 | M13: {=_xlfn.IFS( OR(E13="Absent", E13="Sick Leave Without Pay", E13="Vacation Leave Without Pay", E13="Rest Day"), 0, OR(E13="Approved Sick Leave", E13="Approved Vacation Leave"), 1, D13="Regular Non-Working Holiday", IF(E13="Worked", IF(F13="Yes",2.6,2), 1), D13="Regular Working Holiday", IF(E13="Worked", IF(F13="Yes",2.6,2), 1), D13="Special Non-Working Holiday", IF(E13="Worked", IF(F13="Yes",1.5,1.3), 0), D13="Special Working Holiday", 1, D13="Regular", IF(F13="Yes", IF(E13="Worked",1.3,0), IF(E13="Worked",1,0) ) )} -> 0 | N13: {=_xlfn.IFS( F13="No", _xlfn.IFS( D13="Regular", 1.25, OR(D13="Special Working Holiday", D13="Special Non-Working Holiday"), 1.3*1.3, OR(D13="Regular Working Holiday", D13="Regular Non-Working Holiday"), 2*1.3 ), F13="Yes", _xlfn.IFS( D13="Regular", 1.3*1.3, OR(D13="Special Working Holiday", D13="Special Non-Working Holiday"), 1.5*1.3, OR(D13="Regular Working Holiday", D13="Regular Non-Working Holiday"), 2.6*1.3 ) )} -> 1.69 | O13: =IF(E13<>"",(G13*HPE*M13)+(N13*HPE*J13)+(K13*ND),"") -> 0 | P13: {=_xlfn.IFS( OR(DAY(B13)=5, DAY(B13)=20), "Cut-off", OR(DAY(B13)=6, DAY(B13)=21), "Start", OR( DAY(B13)=15, DAY(B13)=30, AND(MONTH(B13)=2,DAY(B13)=DAY(EOMONTH(B13,0))) ), "Payday", TRUE, "" )} -> Payday | Q13: =SUM(O2:O5) -> 3510.8046
A14: MARCH | B14: 46082 | C14: March | D14: =_xlfn.XLOOKUP(B14,'Holidays 2026'!$A$2:$A$27,'Holidays 2026'!$G$2:$G$27,"Regular",0,1) -> Regular | E14: Rest Day | F14: =IF(OR(TEXT(B14,"dddd")="Saturday",TEXT(B14,"dddd")="Sunday"),"Yes","No") -> Yes | G14: {=_xlfn.IFS(OR(E14="Worked",E14="Approved Sick Leave",E14="Approved Vacation Leave",E14="Holiday"),8,E14="","",OR(E14="Absent",E14="Rest Day",E14="Sick Leave Without Pay",E14="Vacation Leave Without Pay"),0)} -> 0 | H14: 0 | I14: 0 | J14: 0 | K14: =IF(E14="Rest Day",0,"7") -> 0 | M14: {=_xlfn.IFS( OR(E14="Absent", E14="Sick Leave Without Pay", E14="Vacation Leave Without Pay", E14="Rest Day"), 0, OR(E14="Approved Sick Leave", E14="Approved Vacation Leave"), 1, D14="Regular Non-Working Holiday", IF(E14="Worked", IF(F14="Yes",2.6,2), 1), D14="Regular Working Holiday", IF(E14="Worked", IF(F14="Yes",2.6,2), 1), D14="Special Non-Working Holiday", IF(E14="Worked", IF(F14="Yes",1.5,1.3), 0), D14="Special Working Holiday", 1, D14="Regular", IF(F14="Yes", IF(E14="Worked",1.3,0), IF(E14="Worked",1,0) ) )} -> 0 | N14: {=_xlfn.IFS( F14="No", _xlfn.IFS( D14="Regular", 1.25, OR(D14="Special Working Holiday", D14="Special Non-Working Holiday"), 1.3*1.3, OR(D14="Regular Working Holiday", D14="Regular Non-Working Holiday"), 2*1.3 ), F14="Yes", _xlfn.IFS( D14="Regular", 1.3*1.3, OR(D14="Special Working Holiday", D14="Special Non-Working Holiday"), 1.5*1.3, OR(D14="Regular Working Holiday", D14="Regular Non-Working Holiday"), 2.6*1.3 ) )} -> 1.69 | O14: =IF(E14<>"",(G14*HPE*M14)+(N14*HPE*J14)+(K14*ND),"") -> 0 | P14: {=_xlfn.IFS( OR(DAY(B14)=5, DAY(B14)=20), "Cut-off", OR(DAY(B14)=6, DAY(B14)=21), "Start", OR( DAY(B14)=15, DAY(B14)=30, AND(MONTH(B14)=2,DAY(B14)=DAY(EOMONTH(B14,0))) ), "Payday", TRUE, "" )}
B15: 46083 | C15: March | D15: =_xlfn.XLOOKUP(B15,'Holidays 2026'!$A$2:$A$27,'Holidays 2026'!$G$2:$G$27,"Regular",0,1) -> Regular | E15: Worked | F15: =IF(OR(TEXT(B15,"dddd")="Saturday",TEXT(B15,"dddd")="Sunday"),"Yes","No") -> No | G15: {=_xlfn.IFS(OR(E15="Worked",E15="Approved Sick Leave",E15="Approved Vacation Leave",E15="Holiday"),8,E15="","",OR(E15="Absent",E15="Rest Day",E15="Sick Leave Without Pay",E15="Vacation Leave Without Pay"),0)} -> 8 | H15: 0 | I15: 0 | J15: 0 | K15: =IF(E15="Rest Day",0,"7") -> 7 | M15: {=_xlfn.IFS( OR(E15="Absent", E15="Sick Leave Without Pay", E15="Vacation Leave Without Pay", E15="Rest Day"), 0, OR(E15="Approved Sick Leave", E15="Approved Vacation Leave"), 1, D15="Regular Non-Working Holiday", IF(E15="Worked", IF(F15="Yes",2.6,2), 1), D15="Regular Working Holiday", IF(E15="Worked", IF(F15="Yes",2.6,2), 1), D15="Special Non-Working Holiday", IF(E15="Worked", IF(F15="Yes",1.5,1.3), 0), D15="Special Working Holiday", 1, D15="Regular", IF(F15="Yes", IF(E15="Worked",1.3,0), IF(E15="Worked",1,0) ) )} -> 1 | N15: {=_xlfn.IFS( F15="No", _xlfn.IFS( D15="Regular", 1.25, OR(D15="Special Working Holiday", D15="Special Non-Working Holiday"), 1.3*1.3, OR(D15="Regular Working Holiday", D15="Regular Non-Working Holiday"), 2*1.3 ), F15="Yes", _xlfn.IFS( D15="Regular", 1.3*1.3, OR(D15="Special Working Holiday", D15="Special Non-Working Holiday"), 1.5*1.3, OR(D15="Regular Working Holiday", D15="Regular Non-Working Holiday"), 2.6*1.3 ) )} -> 1.25 | O15: =IF(E15<>"",(G15*HPE*M15)+(N15*HPE*J15)+(K15*ND),"") -> 800 | P15: {=_xlfn.IFS( OR(DAY(B15)=5, DAY(B15)=20), "Cut-off", OR(DAY(B15)=6, DAY(B15)=21), "Start", OR( DAY(B15)=15, DAY(B15)=30, AND(MONTH(B15)=2,DAY(B15)=DAY(EOMONTH(B15,0))) ), "Payday", TRUE, "" )}
B16: 46084 | C16: March | D16: =_xlfn.XLOOKUP(B16,'Holidays 2026'!$A$2:$A$27,'Holidays 2026'!$G$2:$G$27,"Regular",0,1) -> Regular | E16: Worked | F16: =IF(OR(TEXT(B16,"dddd")="Saturday",TEXT(B16,"dddd")="Sunday"),"Yes","No") -> No | G16: {=_xlfn.IFS(OR(E16="Worked",E16="Approved Sick Leave",E16="Approved Vacation Leave",E16="Holiday"),8,E16="","",OR(E16="Absent",E16="Rest Day",E16="Sick Leave Without Pay",E16="Vacation Leave Without Pay"),0)} -> 8 | H16: 0 | I16: 0 | J16: 0 | K16: =IF(E16="Rest Day",0,"7") -> 7 | M16: {=_xlfn.IFS( OR(E16="Absent", E16="Sick Leave Without Pay", E16="Vacation Leave Without Pay", E16="Rest Day"), 0, OR(E16="Approved Sick Leave", E16="Approved Vacation Leave"), 1, D16="Regular Non-Working Holiday", IF(E16="Worked", IF(F16="Yes",2.6,2), 1), D16="Regular Working Holiday", IF(E16="Worked", IF(F16="Yes",2.6,2), 1), D16="Special Non-Working Holiday", IF(E16="Worked", IF(F16="Yes",1.5,1.3), 0), D16="Special Working Holiday", 1, D16="Regular", IF(F16="Yes", IF(E16="Worked",1.3,0), IF(E16="Worked",1,0) ) )} -> 1 | N16: {=_xlfn.IFS( F16="No", _xlfn.IFS( D16="Regular", 1.25, OR(D16="Special Working Holiday", D16="Special Non-Working Holiday"), 1.3*1.3, OR(D16="Regular Working Holiday", D16="Regular Non-Working Holiday"), 2*1.3 ), F16="Yes", _xlfn.IFS( D16="Regular", 1.3*1.3, OR(D16="Special Working Holiday", D16="Special Non-Working Holiday"), 1.5*1.3, OR(D16="Regular Working Holiday", D16="Regular Non-Working Holiday"), 2.6*1.3 ) )} -> 1.25 | O16: =IF(E16<>"",(G16*HPE*M16)+(N16*HPE*J16)+(K16*ND),"") -> 800 | P16: {=_xlfn.IFS( OR(DAY(B16)=5, DAY(B16)=20), "Cut-off", OR(DAY(B16)=6, DAY(B16)=21), "Start", OR( DAY(B16)=15, DAY(B16)=30, AND(MONTH(B16)=2,DAY(B16)=DAY(EOMONTH(B16,0))) ), "Payday", TRUE, "" )}
B17: 46085 | C17: March | D17: =_xlfn.XLOOKUP(B17,'Holidays 2026'!$A$2:$A$27,'Holidays 2026'!$G$2:$G$27,"Regular",0,1) -> Regular | E17: Worked | F17: =IF(OR(TEXT(B17,"dddd")="Saturday",TEXT(B17,"dddd")="Sunday"),"Yes","No") -> No | G17: {=_xlfn.IFS(OR(E17="Worked",E17="Approved Sick Leave",E17="Approved Vacation Leave",E17="Holiday"),8,E17="","",OR(E17="Absent",E17="Rest Day",E17="Sick Leave Without Pay",E17="Vacation Leave Without Pay"),0)} -> 8 | H17: 0 | I17: 0 | J17: 0 | K17: =IF(E17="Rest Day",0,"7") -> 7 | M17: {=_xlfn.IFS( OR(E17="Absent", E17="Sick Leave Without Pay", E17="Vacation Leave Without Pay", E17="Rest Day"), 0, OR(E17="Approved Sick Leave", E17="Approved Vacation Leave"), 1, D17="Regular Non-Working Holiday", IF(E17="Worked", IF(F17="Yes",2.6,2), 1), D17="Regular Working Holiday", IF(E17="Worked", IF(F17="Yes",2.6,2), 1), D17="Special Non-Working Holiday", IF(E17="Worked", IF(F17="Yes",1.5,1.3), 0), D17="Special Working Holiday", 1, D17="Regular", IF(F17="Yes", IF(E17="Worked",1.3,0), IF(E17="Worked",1,0) ) )} -> 1 | N17: {=_xlfn.IFS( F17="No", _xlfn.IFS( D17="Regular", 1.25, OR(D17="Special Working Holiday", D17="Special Non-Working Holiday"), 1.3*1.3, OR(D17="Regular Working Holiday", D17="Regular Non-Working Holiday"), 2*1.3 ), F17="Yes", _xlfn.IFS( D17="Regular", 1.3*1.3, OR(D17="Special Working Holiday", D17="Special Non-Working Holiday"), 1.5*1.3, OR(D17="Regular Working Holiday", D17="Regular Non-Working Holiday"), 2.6*1.3 ) )} -> 1.25 | O17: =IF(E17<>"",(G17*HPE*M17)+(N17*HPE*J17)+(K17*ND),"") -> 800 | P17: {=_xlfn.IFS( OR(DAY(B17)=5, DAY(B17)=20), "Cut-off", OR(DAY(B17)=6, DAY(B17)=21), "Start", OR( DAY(B17)=15, DAY(B17)=30, AND(MONTH(B17)=2,DAY(B17)=DAY(EOMONTH(B17,0))) ), "Payday", TRUE, "" )}
B18: 46086 | C18: March | D18: =_xlfn.XLOOKUP(B18,'Holidays 2026'!$A$2:$A$27,'Holidays 2026'!$G$2:$G$27,"Regular",0,1) -> Regular | E18: Worked | F18: =IF(OR(TEXT(B18,"dddd")="Saturday",TEXT(B18,"dddd")="Sunday"),"Yes","No") -> No | G18: {=_xlfn.IFS(OR(E18="Worked",E18="Approved Sick Leave",E18="Approved Vacation Leave",E18="Holiday"),8,E18="","",OR(E18="Absent",E18="Rest Day",E18="Sick Leave Without Pay",E18="Vacation Leave Without Pay"),0)} -> 8 | H18: 0 | I18: 0 | J18: 0 | K18: =IF(E18="Rest Day",0,"7") -> 7 | M18: {=_xlfn.IFS( OR(E18="Absent", E18="Sick Leave Without Pay", E18="Vacation Leave Without Pay", E18="Rest Day"), 0, OR(E18="Approved Sick Leave", E18="Approved Vacation Leave"), 1, D18="Regular Non-Working Holiday", IF(E18="Worked", IF(F18="Yes",2.6,2), 1), D18="Regular Working Holiday", IF(E18="Worked", IF(F18="Yes",2.6,2), 1), D18="Special Non-Working Holiday", IF(E18="Worked", IF(F18="Yes",1.5,1.3), 0), D18="Special Working Holiday", 1, D18="Regular", IF(F18="Yes", IF(E18="Worked",1.3,0), IF(E18="Worked",1,0) ) )} -> 1 | N18: {=_xlfn.IFS( F18="No", _xlfn.IFS( D18="Regular", 1.25, OR(D18="Special Working Holiday", D18="Special Non-Working Holiday"), 1.3*1.3, OR(D18="Regular Working Holiday", D18="Regular Non-Working Holiday"), 2*1.3 ), F18="Yes", _xlfn.IFS( D18="Regular", 1.3*1.3, OR(D18="Special Working Holiday", D18="Special Non-Working Holiday"), 1.5*1.3, OR(D18="Regular Working Holiday", D18="Regular Non-Working Holiday"), 2.6*1.3 ) )} -> 1.25 | O18: =IF(E18<>"",(G18*HPE*M18)+(N18*HPE*J18)+(K18*ND),"") -> 800 | P18: {=_xlfn.IFS( OR(DAY(B18)=5, DAY(B18)=20), "Cut-off", OR(DAY(B18)=6, DAY(B18)=21), "Start", OR( DAY(B18)=15, DAY(B18)=30, AND(MONTH(B18)=2,DAY(B18)=DAY(EOMONTH(B18,0))) ), "Payday", TRUE, "" )} -> Cut-off
B19: 46087 | C19: March | D19: =_xlfn.XLOOKUP(B19,'Holidays 2026'!$A$2:$A$27,'Holidays 2026'!$G$2:$G$27,"Regular",0,1) -> Regular | E19: Worked | F19: =IF(OR(TEXT(B19,"dddd")="Saturday",TEXT(B19,"dddd")="Sunday"),"Yes","No") -> No | G19: {=_xlfn.IFS(OR(E19="Worked",E19="Approved Sick Leave",E19="Approved Vacation Leave",E19="Holiday"),8,E19="","",OR(E19="Absent",E19="Rest Day",E19="Sick Leave Without Pay",E19="Vacation Leave Without Pay"),0)} -> 8 | H19: 0 | I19: 0 | J19: 0 | K19: =IF(E19="Rest Day",0,"7") -> 7 | M19: {=_xlfn.IFS( OR(E19="Absent", E19="Sick Leave Without Pay", E19="Vacation Leave Without Pay", E19="Rest Day"), 0, OR(E19="Approved Sick Leave", E19="Approved Vacation Leave"), 1, D19="Regular Non-Working Holiday", IF(E19="Worked", IF(F19="Yes",2.6,2), 1), D19="Regular Working Holiday", IF(E19="Worked", IF(F19="Yes",2.6,2), 1), D19="Special Non-Working Holiday", IF(E19="Worked", IF(F19="Yes",1.5,1.3), 0), D19="Special Working Holiday", 1, D19="Regular", IF(F19="Yes", IF(E19="Worked",1.3,0), IF(E19="Worked",1,0) ) )} -> 1 | N19: {=_xlfn.IFS( F19="No", _xlfn.IFS( D19="Regular", 1.25, OR(D19="Special Working Holiday", D19="Special Non-Working Holiday"), 1.3*1.3, OR(D19="Regular Working Holiday", D19="Regular Non-Working Holiday"), 2*1.3 ), F19="Yes", _xlfn.IFS( D19="Regular", 1.3*1.3, OR(D19="Special Working Holiday", D19="Special Non-Working Holiday"), 1.5*1.3, OR(D19="Regular Working Holiday", D19="Regular Non-Working Holiday"), 2.6*1.3 ) )} -> 1.25 | O19: =IF(E19<>"",(G19*HPE*M19)+(N19*HPE*J19)+(K19*ND),"") -> 800 | P19: {=_xlfn.IFS( OR(DAY(B19)=5, DAY(B19)=20), "Cut-off", OR(DAY(B19)=6, DAY(B19)=21), "Start", OR( DAY(B19)=15, DAY(B19)=30, AND(MONTH(B19)=2,DAY(B19)=DAY(EOMONTH(B19,0))) ), "Payday", TRUE, "" )} -> Start
B20: 46088 | C20: March | D20: =_xlfn.XLOOKUP(B20,'Holidays 2026'!$A$2:$A$27,'Holidays 2026'!$G$2:$G$27,"Regular",0,1) -> Regular | E20: Rest Day | F20: =IF(OR(TEXT(B20,"dddd")="Saturday",TEXT(B20,"dddd")="Sunday"),"Yes","No") -> Yes | G20: {=_xlfn.IFS(OR(E20="Worked",E20="Approved Sick Leave",E20="Approved Vacation Leave",E20="Holiday"),8,E20="","",OR(E20="Absent",E20="Rest Day",E20="Sick Leave Without Pay",E20="Vacation Leave Without Pay"),0)} -> 0 | H20: 0 | I20: 0 | J20: 0 | K20: =IF(E20="Rest Day",0,"7") -> 0 | M20: {=_xlfn.IFS( OR(E20="Absent", E20="Sick Leave Without Pay", E20="Vacation Leave Without Pay", E20="Rest Day"), 0, OR(E20="Approved Sick Leave", E20="Approved Vacation Leave"), 1, D20="Regular Non-Working Holiday", IF(E20="Worked", IF(F20="Yes",2.6,2), 1), D20="Regular Working Holiday", IF(E20="Worked", IF(F20="Yes",2.6,2), 1), D20="Special Non-Working Holiday", IF(E20="Worked", IF(F20="Yes",1.5,1.3), 0), D20="Special Working Holiday", 1, D20="Regular", IF(F20="Yes", IF(E20="Worked",1.3,0), IF(E20="Worked",1,0) ) )} -> 0 | N20: {=_xlfn.IFS( F20="No", _xlfn.IFS( D20="Regular", 1.25, OR(D20="Special Working Holiday", D20="Special Non-Working Holiday"), 1.3*1.3, OR(D20="Regular Working Holiday", D20="Regular Non-Working Holiday"), 2*1.3 ), F20="Yes", _xlfn.IFS( D20="Regular", 1.3*1.3, OR(D20="Special Working Holiday", D20="Special Non-Working Holiday"), 1.5*1.3, OR(D20="Regular Working Holiday", D20="Regular Non-Working Holiday"), 2.6*1.3 ) )} -> 1.69 | O20: =IF(E20<>"",(G20*HPE*M20)+(N20*HPE*J20)+(K20*ND),"") -> 0 | P20: {=_xlfn.IFS( OR(DAY(B20)=5, DAY(B20)=20), "Cut-off", OR(DAY(B20)=6, DAY(B20)=21), "Start", OR( DAY(B20)=15, DAY(B20)=30, AND(MONTH(B20)=2,DAY(B20)=DAY(EOMONTH(B20,0))) ), "Payday", TRUE, "" )}
B21: 46089 | C21: March | D21: =_xlfn.XLOOKUP(B21,'Holidays 2026'!$A$2:$A$27,'Holidays 2026'!$G$2:$G$27,"Regular",0,1) -> Regular | E21: Rest Day | F21: =IF(OR(TEXT(B21,"dddd")="Saturday",TEXT(B21,"dddd")="Sunday"),"Yes","No") -> Yes | G21: {=_xlfn.IFS(OR(E21="Worked",E21="Approved Sick Leave",E21="Approved Vacation Leave",E21="Holiday"),8,E21="","",OR(E21="Absent",E21="Rest Day",E21="Sick Leave Without Pay",E21="Vacation Leave Without Pay"),0)} -> 0 | H21: 0 | I21: 0 | J21: 0 | K21: =IF(E21="Rest Day",0,"7") -> 0 | M21: {=_xlfn.IFS( OR(E21="Absent", E21="Sick Leave Without Pay", E21="Vacation Leave Without Pay", E21="Rest Day"), 0, OR(E21="Approved Sick Leave", E21="Approved Vacation Leave"), 1, D21="Regular Non-Working Holiday", IF(E21="Worked", IF(F21="Yes",2.6,2), 1), D21="Regular Working Holiday", IF(E21="Worked", IF(F21="Yes",2.6,2), 1), D21="Special Non-Working Holiday", IF(E21="Worked", IF(F21="Yes",1.5,1.3), 0), D21="Special Working Holiday", 1, D21="Regular", IF(F21="Yes", IF(E21="Worked",1.3,0), IF(E21="Worked",1,0) ) )} -> 0 | N21: {=_xlfn.IFS( F21="No", _xlfn.IFS( D21="Regular", 1.25, OR(D21="Special Working Holiday", D21="Special Non-Working Holiday"), 1.3*1.3, OR(D21="Regular Working Holiday", D21="Regular Non-Working Holiday"), 2*1.3 ), F21="Yes", _xlfn.IFS( D21="Regular", 1.3*1.3, OR(D21="Special Working Holiday", D21="Special Non-Working Holiday"), 1.5*1.3, OR(D21="Regular Working Holiday", D21="Regular Non-Working Holiday"), 2.6*1.3 ) )} -> 1.69 | O21: =IF(E21<>"",(G21*HPE*M21)+(N21*HPE*J21)+(K21*ND),"") -> 0 | P21: {=_xlfn.IFS( OR(DAY(B21)=5, DAY(B21)=20), "Cut-off", OR(DAY(B21)=6, DAY(B21)=21), "Start", OR( DAY(B21)=15, DAY(B21)=30, AND(MONTH(B21)=2,DAY(B21)=DAY(EOMONTH(B21,0))) ), "Payday", TRUE, "" )}
B22: 46090 | C22: March | D22: =_xlfn.XLOOKUP(B22,'Holidays 2026'!$A$2:$A$27,'Holidays 2026'!$G$2:$G$27,"Regular",0,1) -> Regular | E22: Worked | F22: =IF(OR(TEXT(B22,"dddd")="Saturday",TEXT(B22,"dddd")="Sunday"),"Yes","No") -> No | G22: {=_xlfn.IFS(OR(E22="Worked",E22="Approved Sick Leave",E22="Approved Vacation Leave",E22="Holiday"),8,E22="","",OR(E22="Absent",E22="Rest Day",E22="Sick Leave Without Pay",E22="Vacation Leave Without Pay"),0)} -> 8 | H22: 0 | I22: 0 | J22: 0 | K22: =IF(E22="Rest Day",0,"7") -> 7 | M22: {=_xlfn.IFS( OR(E22="Absent", E22="Sick Leave Without Pay", E22="Vacation Leave Without Pay", E22="Rest Day"), 0, OR(E22="Approved Sick Leave", E22="Approved Vacation Leave"), 1, D22="Regular Non-Working Holiday", IF(E22="Worked", IF(F22="Yes",2.6,2), 1), D22="Regular Working Holiday", IF(E22="Worked", IF(F22="Yes",2.6,2), 1), D22="Special Non-Working Holiday", IF(E22="Worked", IF(F22="Yes",1.5,1.3), 0), D22="Special Working Holiday", 1, D22="Regular", IF(F22="Yes", IF(E22="Worked",1.3,0), IF(E22="Worked",1,0) ) )} -> 1 | N22: {=_xlfn.IFS( F22="No", _xlfn.IFS( D22="Regular", 1.25, OR(D22="Special Working Holiday", D22="Special Non-Working Holiday"), 1.3*1.3, OR(D22="Regular Working Holiday", D22="Regular Non-Working Holiday"), 2*1.3 ), F22="Yes", _xlfn.IFS( D22="Regular", 1.3*1.3, OR(D22="Special Working Holiday", D22="Special Non-Working Holiday"), 1.5*1.3, OR(D22="Regular Working Holiday", D22="Regular Non-Working Holiday"), 2.6*1.3 ) )} -> 1.25 | O22: =IF(E22<>"",(G22*HPE*M22)+(N22*HPE*J22)+(K22*ND),"") -> 800 | P22: {=_xlfn.IFS( OR(DAY(B22)=5, DAY(B22)=20), "Cut-off", OR(DAY(B22)=6, DAY(B22)=21), "Start", OR( DAY(B22)=15, DAY(B22)=30, AND(MONTH(B22)=2,DAY(B22)=DAY(EOMONTH(B22,0))) ), "Payday", TRUE, "" )}
B23: 46091 | C23: March | D23: =_xlfn.XLOOKUP(B23,'Holidays 2026'!$A$2:$A$27,'Holidays 2026'!$G$2:$G$27,"Regular",0,1) -> Regular | E23: Worked | F23: =IF(OR(TEXT(B23,"dddd")="Saturday",TEXT(B23,"dddd")="Sunday"),"Yes","No") -> No | G23: {=_xlfn.IFS(OR(E23="Worked",E23="Approved Sick Leave",E23="Approved Vacation Leave",E23="Holiday"),8,E23="","",OR(E23="Absent",E23="Rest Day",E23="Sick Leave Without Pay",E23="Vacation Leave Without Pay"),0)} -> 8 | H23: 0 | I23: 0 | J23: 0 | K23: =IF(E23="Rest Day",0,"7") -> 7 | M23: {=_xlfn.IFS( OR(E23="Absent", E23="Sick Leave Without Pay", E23="Vacation Leave Without Pay", E23="Rest Day"), 0, OR(E23="Approved Sick Leave", E23="Approved Vacation Leave"), 1, D23="Regular Non-Working Holiday", IF(E23="Worked", IF(F23="Yes",2.6,2), 1), D23="Regular Working Holiday", IF(E23="Worked", IF(F23="Yes",2.6,2), 1), D23="Special Non-Working Holiday", IF(E23="Worked", IF(F23="Yes",1.5,1.3), 0), D23="Special Working Holiday", 1, D23="Regular", IF(F23="Yes", IF(E23="Worked",1.3,0), IF(E23="Worked",1,0) ) )} -> 1 | N23: {=_xlfn.IFS( F23="No", _xlfn.IFS( D23="Regular", 1.25, OR(D23="Special Working Holiday", D23="Special Non-Working Holiday"), 1.3*1.3, OR(D23="Regular Working Holiday", D23="Regular Non-Working Holiday"), 2*1.3 ), F23="Yes", _xlfn.IFS( D23="Regular", 1.3*1.3, OR(D23="Special Working Holiday", D23="Special Non-Working Holiday"), 1.5*1.3, OR(D23="Regular Working Holiday", D23="Regular Non-Working Holiday"), 2.6*1.3 ) )} -> 1.25 | O23: =IF(E23<>"",(G23*HPE*M23)+(N23*HPE*J23)+(K23*ND),"") -> 800 | P23: {=_xlfn.IFS( OR(DAY(B23)=5, DAY(B23)=20), "Cut-off", OR(DAY(B23)=6, DAY(B23)=21), "Start", OR( DAY(B23)=15, DAY(B23)=30, AND(MONTH(B23)=2,DAY(B23)=DAY(EOMONTH(B23,0))) ), "Payday", TRUE, "" )}
B24: 46092 | C24: March | D24: =_xlfn.XLOOKUP(B24,'Holidays 2026'!$A$2:$A$27,'Holidays 2026'!$G$2:$G$27,"Regular",0,1) -> Regular | E24: Worked | F24: =IF(OR(TEXT(B24,"dddd")="Saturday",TEXT(B24,"dddd")="Sunday"),"Yes","No") -> No | G24: {=_xlfn.IFS(OR(E24="Worked",E24="Approved Sick Leave",E24="Approved Vacation Leave",E24="Holiday"),8,E24="","",OR(E24="Absent",E24="Rest Day",E24="Sick Leave Without Pay",E24="Vacation Leave Without Pay"),0)} -> 8 | H24: 0 | I24: 0 | J24: 0 | K24: =IF(E24="Rest Day",0,"7") -> 7 | M24: {=_xlfn.IFS( OR(E24="Absent", E24="Sick Leave Without Pay", E24="Vacation Leave Without Pay", E24="Rest Day"), 0, OR(E24="Approved Sick Leave", E24="Approved Vacation Leave"), 1, D24="Regular Non-Working Holiday", IF(E24="Worked", IF(F24="Yes",2.6,2), 1), D24="Regular Working Holiday", IF(E24="Worked", IF(F24="Yes",2.6,2), 1), D24="Special Non-Working Holiday", IF(E24="Worked", IF(F24="Yes",1.5,1.3), 0), D24="Special Working Holiday", 1, D24="Regular", IF(F24="Yes", IF(E24="Worked",1.3,0), IF(E24="Worked",1,0) ) )} -> 1 | N24: {=_xlfn.IFS( F24="No", _xlfn.IFS( D24="Regular", 1.25, OR(D24="Special Working Holiday", D24="Special Non-Working Holiday"), 1.3*1.3, OR(D24="Regular Working Holiday", D24="Regular Non-Working Holiday"), 2*1.3 ), F24="Yes", _xlfn.IFS( D24="Regular", 1.3*1.3, OR(D24="Special Working Holiday", D24="Special Non-Working Holiday"), 1.5*1.3, OR(D24="Regular Working Holiday", D24="Regular Non-Working Holiday"), 2.6*1.3 ) )} -> 1.25 | O24: =IF(E24<>"",(G24*HPE*M24)+(N24*HPE*J24)+(K24*ND),"") -> 800 | P24: {=_xlfn.IFS( OR(DAY(B24)=5, DAY(B24)=20), "Cut-off", OR(DAY(B24)=6, DAY(B24)=21), "Start", OR( DAY(B24)=15, DAY(B24)=30, AND(MONTH(B24)=2,DAY(B24)=DAY(EOMONTH(B24,0))) ), "Payday", TRUE, "" )}
B25: 46093 | C25: March | D25: =_xlfn.XLOOKUP(B25,'Holidays 2026'!$A$2:$A$27,'Holidays 2026'!$G$2:$G$27,"Regular",0,1) -> Regular | E25: Worked | F25: =IF(OR(TEXT(B25,"dddd")="Saturday",TEXT(B25,"dddd")="Sunday"),"Yes","No") -> No | G25: {=_xlfn.IFS(OR(E25="Worked",E25="Approved Sick Leave",E25="Approved Vacation Leave",E25="Holiday"),8,E25="","",OR(E25="Absent",E25="Rest Day",E25="Sick Leave Without Pay",E25="Vacation Leave Without Pay"),0)} -> 8 | H25: 0 | I25: 0 | J25: 0 | K25: =IF(E25="Rest Day",0,"7") -> 7 | M25: {=_xlfn.IFS( OR(E25="Absent", E25="Sick Leave Without Pay", E25="Vacation Leave Without Pay", E25="Rest Day"), 0, OR(E25="Approved Sick Leave", E25="Approved Vacation Leave"), 1, D25="Regular Non-Working Holiday", IF(E25="Worked", IF(F25="Yes",2.6,2), 1), D25="Regular Working Holiday", IF(E25="Worked", IF(F25="Yes",2.6,2), 1), D25="Special Non-Working Holiday", IF(E25="Worked", IF(F25="Yes",1.5,1.3), 0), D25="Special Working Holiday", 1, D25="Regular", IF(F25="Yes", IF(E25="Worked",1.3,0), IF(E25="Worked",1,0) ) )} -> 1 | N25: {=_xlfn.IFS( F25="No", _xlfn.IFS( D25="Regular", 1.25, OR(D25="Special Working Holiday", D25="Special Non-Working Holiday"), 1.3*1.3, OR(D25="Regular Working Holiday", D25="Regular Non-Working Holiday"), 2*1.3 ), F25="Yes", _xlfn.IFS( D25="Regular", 1.3*1.3, OR(D25="Special Working Holiday", D25="Special Non-Working Holiday"), 1.5*1.3, OR(D25="Regular Working Holiday", D25="Regular Non-Working Holiday"), 2.6*1.3 ) )} -> 1.25 | O25: =IF(E25<>"",(G25*HPE*M25)+(N25*HPE*J25)+(K25*ND),"") -> 800 | P25: {=_xlfn.IFS( OR(DAY(B25)=5, DAY(B25)=20), "Cut-off", OR(DAY(B25)=6, DAY(B25)=21), "Start", OR( DAY(B25)=15, DAY(B25)=30, AND(MONTH(B25)=2,DAY(B25)=DAY(EOMONTH(B25,0))) ), "Payday", TRUE, "" )}
B26: 46094 | C26: March | D26: =_xlfn.XLOOKUP(B26,'Holidays 2026'!$A$2:$A$27,'Holidays 2026'!$G$2:$G$27,"Regular",0,1) -> Regular | E26: Worked | F26: =IF(OR(TEXT(B26,"dddd")="Saturday",TEXT(B26,"dddd")="Sunday"),"Yes","No") -> No | G26: {=_xlfn.IFS(OR(E26="Worked",E26="Approved Sick Leave",E26="Approved Vacation Leave",E26="Holiday"),8,E26="","",OR(E26="Absent",E26="Rest Day",E26="Sick Leave Without Pay",E26="Vacation Leave Without Pay"),0)} -> 8 | H26: 0 | I26: 0 | J26: 0 | K26: =IF(E26="Rest Day",0,"7") -> 7 | M26: {=_xlfn.IFS( OR(E26="Absent", E26="Sick Leave Without Pay", E26="Vacation Leave Without Pay", E26="Rest Day"), 0, OR(E26="Approved Sick Leave", E26="Approved Vacation Leave"), 1, D26="Regular Non-Working Holiday", IF(E26="Worked", IF(F26="Yes",2.6,2), 1), D26="Regular Working Holiday", IF(E26="Worked", IF(F26="Yes",2.6,2), 1), D26="Special Non-Working Holiday", IF(E26="Worked", IF(F26="Yes",1.5,1.3), 0), D26="Special Working Holiday", 1, D26="Regular", IF(F26="Yes", IF(E26="Worked",1.3,0), IF(E26="Worked",1,0) ) )} -> 1 | N26: {=_xlfn.IFS( F26="No", _xlfn.IFS( D26="Regular", 1.25, OR(D26="Special Working Holiday", D26="Special Non-Working Holiday"), 1.3*1.3, OR(D26="Regular Working Holiday", D26="Regular Non-Working Holiday"), 2*1.3 ), F26="Yes", _xlfn.IFS( D26="Regular", 1.3*1.3, OR(D26="Special Working Holiday", D26="Special Non-Working Holiday"), 1.5*1.3, OR(D26="Regular Working Holiday", D26="Regular Non-Working Holiday"), 2.6*1.3 ) )} -> 1.25 | O26: =IF(E26<>"",(G26*HPE*M26)+(N26*HPE*J26)+(K26*ND),"") -> 800 | P26: {=_xlfn.IFS( OR(DAY(B26)=5, DAY(B26)=20), "Cut-off", OR(DAY(B26)=6, DAY(B26)=21), "Start", OR( DAY(B26)=15, DAY(B26)=30, AND(MONTH(B26)=2,DAY(B26)=DAY(EOMONTH(B26,0))) ), "Payday", TRUE, "" )}
B27: 46095 | C27: March | D27: =_xlfn.XLOOKUP(B27,'Holidays 2026'!$A$2:$A$27,'Holidays 2026'!$G$2:$G$27,"Regular",0,1) -> Regular | E27: Rest Day | F27: =IF(OR(TEXT(B27,"dddd")="Saturday",TEXT(B27,"dddd")="Sunday"),"Yes","No") -> Yes | G27: {=_xlfn.IFS(OR(E27="Worked",E27="Approved Sick Leave",E27="Approved Vacation Leave",E27="Holiday"),8,E27="","",OR(E27="Absent",E27="Rest Day",E27="Sick Leave Without Pay",E27="Vacation Leave Without Pay"),0)} -> 0 | H27: 0 | I27: 0 | J27: 0 | K27: =IF(E27="Rest Day",0,"7") -> 0 | M27: {=_xlfn.IFS( OR(E27="Absent", E27="Sick Leave Without Pay", E27="Vacation Leave Without Pay", E27="Rest Day"), 0, OR(E27="Approved Sick Leave", E27="Approved Vacation Leave"), 1, D27="Regular Non-Working Holiday", IF(E27="Worked", IF(F27="Yes",2.6,2), 1), D27="Regular Working Holiday", IF(E27="Worked", IF(F27="Yes",2.6,2), 1), D27="Special Non-Working Holiday", IF(E27="Worked", IF(F27="Yes",1.5,1.3), 0), D27="Special Working Holiday", 1, D27="Regular", IF(F27="Yes", IF(E27="Worked",1.3,0), IF(E27="Worked",1,0) ) )} -> 0 | N27: {=_xlfn.IFS( F27="No", _xlfn.IFS( D27="Regular", 1.25, OR(D27="Special Working Holiday", D27="Special Non-Working Holiday"), 1.3*1.3, OR(D27="Regular Working Holiday", D27="Regular Non-Working Holiday"), 2*1.3 ), F27="Yes", _xlfn.IFS( D27="Regular", 1.3*1.3, OR(D27="Special Working Holiday", D27="Special Non-Working Holiday"), 1.5*1.3, OR(D27="Regular Working Holiday", D27="Regular Non-Working Holiday"), 2.6*1.3 ) )} -> 1.69 | O27: =IF(E27<>"",(G27*HPE*M27)+(N27*HPE*J27)+(K27*ND),"") -> 0 | P27: {=_xlfn.IFS( OR(DAY(B27)=5, DAY(B27)=20), "Cut-off", OR(DAY(B27)=6, DAY(B27)=21), "Start", OR( DAY(B27)=15, DAY(B27)=30, AND(MONTH(B27)=2,DAY(B27)=DAY(EOMONTH(B27,0))) ), "Payday", TRUE, "" )}
B28: 46096 | C28: March | D28: =_xlfn.XLOOKUP(B28,'Holidays 2026'!$A$2:$A$27,'Holidays 2026'!$G$2:$G$27,"Regular",0,1) -> Regular | E28: Rest Day | F28: =IF(OR(TEXT(B28,"dddd")="Saturday",TEXT(B28,"dddd")="Sunday"),"Yes","No") -> Yes | G28: {=_xlfn.IFS(OR(E28="Worked",E28="Approved Sick Leave",E28="Approved Vacation Leave",E28="Holiday"),8,E28="","",OR(E28="Absent",E28="Rest Day",E28="Sick Leave Without Pay",E28="Vacation Leave Without Pay"),0)} -> 0 | H28: 0 | I28: 0 | J28: 0 | K28: =IF(E28="Rest Day",0,"7") -> 0 | M28: {=_xlfn.IFS( OR(E28="Absent", E28="Sick Leave Without Pay", E28="Vacation Leave Without Pay", E28="Rest Day"), 0, OR(E28="Approved Sick Leave", E28="Approved Vacation Leave"), 1, D28="Regular Non-Working Holiday", IF(E28="Worked", IF(F28="Yes",2.6,2), 1), D28="Regular Working Holiday", IF(E28="Worked", IF(F28="Yes",2.6,2), 1), D28="Special Non-Working Holiday", IF(E28="Worked", IF(F28="Yes",1.5,1.3), 0), D28="Special Working Holiday", 1, D28="Regular", IF(F28="Yes", IF(E28="Worked",1.3,0), IF(E28="Worked",1,0) ) )} -> 0 | N28: {=_xlfn.IFS( F28="No", _xlfn.IFS( D28="Regular", 1.25, OR(D28="Special Working Holiday", D28="Special Non-Working Holiday"), 1.3*1.3, OR(D28="Regular Working Holiday", D28="Regular Non-Working Holiday"), 2*1.3 ), F28="Yes", _xlfn.IFS( D28="Regular", 1.3*1.3, OR(D28="Special Working Holiday", D28="Special Non-Working Holiday"), 1.5*1.3, OR(D28="Regular Working Holiday", D28="Regular Non-Working Holiday"), 2.6*1.3 ) )} -> 1.69 | O28: =IF(E28<>"",(G28*HPE*M28)+(N28*HPE*J28)+(K28*ND),"") -> 0 | P28: {=_xlfn.IFS( OR(DAY(B28)=5, DAY(B28)=20), "Cut-off", OR(DAY(B28)=6, DAY(B28)=21), "Start", OR( DAY(B28)=15, DAY(B28)=30, AND(MONTH(B28)=2,DAY(B28)=DAY(EOMONTH(B28,0))) ), "Payday", TRUE, "" )} -> Payday | Q28: =SUM(O6:O18) -> 7200
B29: 46097 | C29: March | D29: =_xlfn.XLOOKUP(B29,'Holidays 2026'!$A$2:$A$27,'Holidays 2026'!$G$2:$G$27,"Regular",0,1) -> Regular | E29: Worked | F29: =IF(OR(TEXT(B29,"dddd")="Saturday",TEXT(B29,"dddd")="Sunday"),"Yes","No") -> No | G29: {=_xlfn.IFS(OR(E29="Worked",E29="Approved Sick Leave",E29="Approved Vacation Leave",E29="Holiday"),8,E29="","",OR(E29="Absent",E29="Rest Day",E29="Sick Leave Without Pay",E29="Vacation Leave Without Pay"),0)} -> 8 | H29: 0 | I29: 0 | J29: 0 | K29: =IF(E29="Rest Day",0,"7") -> 7 | M29: {=_xlfn.IFS( OR(E29="Absent", E29="Sick Leave Without Pay", E29="Vacation Leave Without Pay", E29="Rest Day"), 0, OR(E29="Approved Sick Leave", E29="Approved Vacation Leave"), 1, D29="Regular Non-Working Holiday", IF(E29="Worked", IF(F29="Yes",2.6,2), 1), D29="Regular Working Holiday", IF(E29="Worked", IF(F29="Yes",2.6,2), 1), D29="Special Non-Working Holiday", IF(E29="Worked", IF(F29="Yes",1.5,1.3), 0), D29="Special Working Holiday", 1, D29="Regular", IF(F29="Yes", IF(E29="Worked",1.3,0), IF(E29="Worked",1,0) ) )} -> 1 | N29: {=_xlfn.IFS( F29="No", _xlfn.IFS( D29="Regular", 1.25, OR(D29="Special Working Holiday", D29="Special Non-Working Holiday"), 1.3*1.3, OR(D29="Regular Working Holiday", D29="Regular Non-Working Holiday"), 2*1.3 ), F29="Yes", _xlfn.IFS( D29="Regular", 1.3*1.3, OR(D29="Special Working Holiday", D29="Special Non-Working Holiday"), 1.5*1.3, OR(D29="Regular Working Holiday", D29="Regular Non-Working Holiday"), 2.6*1.3 ) )} -> 1.25 | O29: =IF(E29<>"",(G29*HPE*M29)+(N29*HPE*J29)+(K29*ND),"") -> 800 | P29: {=_xlfn.IFS( OR(DAY(B29)=5, DAY(B29)=20), "Cut-off", OR(DAY(B29)=6, DAY(B29)=21), "Start", OR( DAY(B29)=15, DAY(B29)=30, AND(MONTH(B29)=2,DAY(B29)=DAY(EOMONTH(B29,0))) ), "Payday", TRUE, "" )}
B30: 46098 | C30: March | D30: =_xlfn.XLOOKUP(B30,'Holidays 2026'!$A$2:$A$27,'Holidays 2026'!$G$2:$G$27,"Regular",0,1) -> Regular | E30: Worked | F30: =IF(OR(TEXT(B30,"dddd")="Saturday",TEXT(B30,"dddd")="Sunday"),"Yes","No") -> No | G30: {=_xlfn.IFS(OR(E30="Worked",E30="Approved Sick Leave",E30="Approved Vacation Leave",E30="Holiday"),8,E30="","",OR(E30="Absent",E30="Rest Day",E30="Sick Leave Without Pay",E30="Vacation Leave Without Pay"),0)} -> 8 | H30: 0 | I30: 0 | J30: 0 | K30: =IF(E30="Rest Day",0,"7") -> 7 | M30: {=_xlfn.IFS( OR(E30="Absent", E30="Sick Leave Without Pay", E30="Vacation Leave Without Pay", E30="Rest Day"), 0, OR(E30="Approved Sick Leave", E30="Approved Vacation Leave"), 1, D30="Regular Non-Working Holiday", IF(E30="Worked", IF(F30="Yes",2.6,2), 1), D30="Regular Working Holiday", IF(E30="Worked", IF(F30="Yes",2.6,2), 1), D30="Special Non-Working Holiday", IF(E30="Worked", IF(F30="Yes",1.5,1.3), 0), D30="Special Working Holiday", 1, D30="Regular", IF(F30="Yes", IF(E30="Worked",1.3,0), IF(E30="Worked",1,0) ) )} -> 1 | N30: {=_xlfn.IFS( F30="No", _xlfn.IFS( D30="Regular", 1.25, OR(D30="Special Working Holiday", D30="Special Non-Working Holiday"), 1.3*1.3, OR(D30="Regular Working Holiday", D30="Regular Non-Working Holiday"), 2*1.3 ), F30="Yes", _xlfn.IFS( D30="Regular", 1.3*1.3, OR(D30="Special Working Holiday", D30="Special Non-Working Holiday"), 1.5*1.3, OR(D30="Regular Working Holiday", D30="Regular Non-Working Holiday"), 2.6*1.3 ) )} -> 1.25 | O30: =IF(E30<>"",(G30*HPE*M30)+(N30*HPE*J30)+(K30*ND),"") -> 800 | P30: {=_xlfn.IFS( OR(DAY(B30)=5, DAY(B30)=20), "Cut-off", OR(DAY(B30)=6, DAY(B30)=21), "Start", OR( DAY(B30)=15, DAY(B30)=30, AND(MONTH(B30)=2,DAY(B30)=DAY(EOMONTH(B30,0))) ), "Payday", TRUE, "" )}
B31: 46099 | C31: March | D31: =_xlfn.XLOOKUP(B31,'Holidays 2026'!$A$2:$A$27,'Holidays 2026'!$G$2:$G$27,"Regular",0,1) -> Regular | E31: Worked | F31: =IF(OR(TEXT(B31,"dddd")="Saturday",TEXT(B31,"dddd")="Sunday"),"Yes","No") -> No | G31: {=_xlfn.IFS(OR(E31="Worked",E31="Approved Sick Leave",E31="Approved Vacation Leave",E31="Holiday"),8,E31="","",OR(E31="Absent",E31="Rest Day",E31="Sick Leave Without Pay",E31="Vacation Leave Without Pay"),0)} -> 8 | H31: 0 | I31: 0 | J31: 0 | K31: =IF(E31="Rest Day",0,"7") -> 7 | M31: {=_xlfn.IFS( OR(E31="Absent", E31="Sick Leave Without Pay", E31="Vacation Leave Without Pay", E31="Rest Day"), 0, OR(E31="Approved Sick Leave", E31="Approved Vacation Leave"), 1, D31="Regular Non-Working Holiday", IF(E31="Worked", IF(F31="Yes",2.6,2), 1), D31="Regular Working Holiday", IF(E31="Worked", IF(F31="Yes",2.6,2), 1), D31="Special Non-Working Holiday", IF(E31="Worked", IF(F31="Yes",1.5,1.3), 0), D31="Special Working Holiday", 1, D31="Regular", IF(F31="Yes", IF(E31="Worked",1.3,0), IF(E31="Worked",1,0) ) )} -> 1 | N31: {=_xlfn.IFS( F31="No", _xlfn.IFS( D31="Regular", 1.25, OR(D31="Special Working Holiday", D31="Special Non-Working Holiday"), 1.3*1.3, OR(D31="Regular Working Holiday", D31="Regular Non-Working Holiday"), 2*1.3 ), F31="Yes", _xlfn.IFS( D31="Regular", 1.3*1.3, OR(D31="Special Working Holiday", D31="Special Non-Working Holiday"), 1.5*1.3, OR(D31="Regular Working Holiday", D31="Regular Non-Working Holiday"), 2.6*1.3 ) )} -> 1.25 | O31: =IF(E31<>"",(G31*HPE*M31)+(N31*HPE*J31)+(K31*ND),"") -> 800 | P31: {=_xlfn.IFS( OR(DAY(B31)=5, DAY(B31)=20), "Cut-off", OR(DAY(B31)=6, DAY(B31)=21), "Start", OR( DAY(B31)=15, DAY(B31)=30, AND(MONTH(B31)=2,DAY(B31)=DAY(EOMONTH(B31,0))) ), "Payday", TRUE, "" )}
B32: 46100 | C32: March | D32: =_xlfn.XLOOKUP(B32,'Holidays 2026'!$A$2:$A$27,'Holidays 2026'!$G$2:$G$27,"Regular",0,1) -> Regular | E32: Worked | F32: =IF(OR(TEXT(B32,"dddd")="Saturday",TEXT(B32,"dddd")="Sunday"),"Yes","No") -> No | G32: {=_xlfn.IFS(OR(E32="Worked",E32="Approved Sick Leave",E32="Approved Vacation Leave",E32="Holiday"),8,E32="","",OR(E32="Absent",E32="Rest Day",E32="Sick Leave Without Pay",E32="Vacation Leave Without Pay"),0)} -> 8 | H32: 0 | I32: 0 | J32: 0 | K32: =IF(E32="Rest Day",0,"7") -> 7 | M32: {=_xlfn.IFS( OR(E32="Absent", E32="Sick Leave Without Pay", E32="Vacation Leave Without Pay", E32="Rest Day"), 0, OR(E32="Approved Sick Leave", E32="Approved Vacation Leave"), 1, D32="Regular Non-Working Holiday", IF(E32="Worked", IF(F32="Yes",2.6,2), 1), D32="Regular Working Holiday", IF(E32="Worked", IF(F32="Yes",2.6,2), 1), D32="Special Non-Working Holiday", IF(E32="Worked", IF(F32="Yes",1.5,1.3), 0), D32="Special Working Holiday", 1, D32="Regular", IF(F32="Yes", IF(E32="Worked",1.3,0), IF(E32="Worked",1,0) ) )} -> 1 | N32: {=_xlfn.IFS( F32="No", _xlfn.IFS( D32="Regular", 1.25, OR(D32="Special Working Holiday", D32="Special Non-Working Holiday"), 1.3*1.3, OR(D32="Regular Working Holiday", D32="Regular Non-Working Holiday"), 2*1.3 ), F32="Yes", _xlfn.IFS( D32="Regular", 1.3*1.3, OR(D32="Special Working Holiday", D32="Special Non-Working Holiday"), 1.5*1.3, OR(D32="Regular Working Holiday", D32="Regular Non-Working Holiday"), 2.6*1.3 ) )} -> 1.25 | O32: =IF(E32<>"",(G32*HPE*M32)+(N32*HPE*J32)+(K32*ND),"") -> 800 | P32: {=_xlfn.IFS( OR(DAY(B32)=5, DAY(B32)=20), "Cut-off", OR(DAY(B32)=6, DAY(B32)=21), "Start", OR( DAY(B32)=15, DAY(B32)=30, AND(MONTH(B32)=2,DAY(B32)=DAY(EOMONTH(B32,0))) ), "Payday", TRUE, "" )}
B33: 46101 | C33: March | D33: =_xlfn.XLOOKUP(B33,'Holidays 2026'!$A$2:$A$27,'Holidays 2026'!$G$2:$G$27,"Regular",0,1) -> Regular Working Holiday | E33: Worked | F33: =IF(OR(TEXT(B33,"dddd")="Saturday",TEXT(B33,"dddd")="Sunday"),"Yes","No") -> No | G33: {=_xlfn.IFS(OR(E33="Worked",E33="Approved Sick Leave",E33="Approved Vacation Leave",E33="Holiday"),8,E33="","",OR(E33="Absent",E33="Rest Day",E33="Sick Leave Without Pay",E33="Vacation Leave Without Pay"),0)} -> 8 | H33: 0 | I33: 0 | J33: 0 | K33: =IF(E33="Rest Day",0,"7") -> 7 | M33: {=_xlfn.IFS( OR(E33="Absent", E33="Sick Leave Without Pay", E33="Vacation Leave Without Pay", E33="Rest Day"), 0, OR(E33="Approved Sick Leave", E33="Approved Vacation Leave"), 1, D33="Regular Non-Working Holiday", IF(E33="Worked", IF(F33="Yes",2.6,2), 1), D33="Regular Working Holiday", IF(E33="Worked", IF(F33="Yes",2.6,2), 1), D33="Special Non-Working Holiday", IF(E33="Worked", IF(F33="Yes",1.5,1.3), 0), D33="Special Working Holiday", 1, D33="Regular", IF(F33="Yes", IF(E33="Worked",1.3,0), IF(E33="Worked",1,0) ) )} -> 2 | N33: {=_xlfn.IFS( F33="No", _xlfn.IFS( D33="Regular", 1.25, OR(D33="Special Working Holiday", D33="Special Non-Working Holiday"), 1.3*1.3, OR(D33="Regular Working Holiday", D33="Regular Non-Working Holiday"), 2*1.3 ), F33="Yes", _xlfn.IFS( D33="Regular", 1.3*1.3, OR(D33="Special Working Holiday", D33="Special Non-Working Holiday"), 1.5*1.3, OR(D33="Regular Working Holiday", D33="Regular Non-Working Holiday"), 2.6*1.3 ) )} -> 2.6 | O33: =IF(E33<>"",(G33*HPE*M33)+(N33*HPE*J33)+(K33*ND),"") -> 1535.6322 | P33: {=_xlfn.IFS( OR(DAY(B33)=5, DAY(B33)=20), "Cut-off", OR(DAY(B33)=6, DAY(B33)=21), "Start", OR( DAY(B33)=15, DAY(B33)=30, AND(MONTH(B33)=2,DAY(B33)=DAY(EOMONTH(B33,0))) ), "Payday", TRUE, "" )} -> Cut-off
B34: 46102 | C34: March | D34: =_xlfn.XLOOKUP(B34,'Holidays 2026'!$A$2:$A$27,'Holidays 2026'!$G$2:$G$27,"Regular",0,1) -> Regular | E34: Rest Day | F34: =IF(OR(TEXT(B34,"dddd")="Saturday",TEXT(B34,"dddd")="Sunday"),"Yes","No") -> Yes | G34: {=_xlfn.IFS(OR(E34="Worked",E34="Approved Sick Leave",E34="Approved Vacation Leave",E34="Holiday"),8,E34="","",OR(E34="Absent",E34="Rest Day",E34="Sick Leave Without Pay",E34="Vacation Leave Without Pay"),0)} -> 0 | H34: 0 | I34: 0 | J34: 0 | K34: =IF(E34="Rest Day",0,"7") -> 0 | M34: {=_xlfn.IFS( OR(E34="Absent", E34="Sick Leave Without Pay", E34="Vacation Leave Without Pay", E34="Rest Day"), 0, OR(E34="Approved Sick Leave", E34="Approved Vacation Leave"), 1, D34="Regular Non-Working Holiday", IF(E34="Worked", IF(F34="Yes",2.6,2), 1), D34="Regular Working Holiday", IF(E34="Worked", IF(F34="Yes",2.6,2), 1), D34="Special Non-Working Holiday", IF(E34="Worked", IF(F34="Yes",1.5,1.3), 0), D34="Special Working Holiday", 1, D34="Regular", IF(F34="Yes", IF(E34="Worked",1.3,0), IF(E34="Worked",1,0) ) )} -> 0 | N34: {=_xlfn.IFS( F34="No", _xlfn.IFS( D34="Regular", 1.25, OR(D34="Special Working Holiday", D34="Special Non-Working Holiday"), 1.3*1.3, OR(D34="Regular Working Holiday", D34="Regular Non-Working Holiday"), 2*1.3 ), F34="Yes", _xlfn.IFS( D34="Regular", 1.3*1.3, OR(D34="Special Working Holiday", D34="Special Non-Working Holiday"), 1.5*1.3, OR(D34="Regular Working Holiday", D34="Regular Non-Working Holiday"), 2.6*1.3 ) )} -> 1.69 | O34: =IF(E34<>"",(G34*HPE*M34)+(N34*HPE*J34)+(K34*ND),"") -> 0 | P34: {=_xlfn.IFS( OR(DAY(B34)=5, DAY(B34)=20), "Cut-off", OR(DAY(B34)=6, DAY(B34)=21), "Start", OR( DAY(B34)=15, DAY(B34)=30, AND(MONTH(B34)=2,DAY(B34)=DAY(EOMONTH(B34,0))) ), "Payday", TRUE, "" )} -> Start
B35: 46103 | C35: March | D35: =_xlfn.XLOOKUP(B35,'Holidays 2026'!$A$2:$A$27,'Holidays 2026'!$G$2:$G$27,"Regular",0,1) -> Regular | E35: Rest Day | F35: =IF(OR(TEXT(B35,"dddd")="Saturday",TEXT(B35,"dddd")="Sunday"),"Yes","No") -> Yes | G35: {=_xlfn.IFS(OR(E35="Worked",E35="Approved Sick Leave",E35="Approved Vacation Leave",E35="Holiday"),8,E35="","",OR(E35="Absent",E35="Rest Day",E35="Sick Leave Without Pay",E35="Vacation Leave Without Pay"),0)} -> 0 | H35: 0 | I35: 0 | J35: 0 | K35: =IF(E35="Rest Day",0,"7") -> 0 | M35: {=_xlfn.IFS( OR(E35="Absent", E35="Sick Leave Without Pay", E35="Vacation Leave Without Pay", E35="Rest Day"), 0, OR(E35="Approved Sick Leave", E35="Approved Vacation Leave"), 1, D35="Regular Non-Working Holiday", IF(E35="Worked", IF(F35="Yes",2.6,2), 1), D35="Regular Working Holiday", IF(E35="Worked", IF(F35="Yes",2.6,2), 1), D35="Special Non-Working Holiday", IF(E35="Worked", IF(F35="Yes",1.5,1.3), 0), D35="Special Working Holiday", 1, D35="Regular", IF(F35="Yes", IF(E35="Worked",1.3,0), IF(E35="Worked",1,0) ) )} -> 0 | N35: {=_xlfn.IFS( F35="No", _xlfn.IFS( D35="Regular", 1.25, OR(D35="Special Working Holiday", D35="Special Non-Working Holiday"), 1.3*1.3, OR(D35="Regular Working Holiday", D35="Regular Non-Working Holiday"), 2*1.3 ), F35="Yes", _xlfn.IFS( D35="Regular", 1.3*1.3, OR(D35="Special Working Holiday", D35="Special Non-Working Holiday"), 1.5*1.3, OR(D35="Regular Working Holiday", D35="Regular Non-Working Holiday"), 2.6*1.3 ) )} -> 1.69 | O35: =IF(E35<>"",(G35*HPE*M35)+(N35*HPE*J35)+(K35*ND),"") -> 0 | P35: {=_xlfn.IFS( OR(DAY(B35)=5, DAY(B35)=20), "Cut-off", OR(DAY(B35)=6, DAY(B35)=21), "Start", OR( DAY(B35)=15, DAY(B35)=30, AND(MONTH(B35)=2,DAY(B35)=DAY(EOMONTH(B35,0))) ), "Payday", TRUE, "" )}
